2024-07-11 20:15:22,770 -  nornir.core -     INFO -        run() - Running task 'fetch_vyos_config' with args {} on 1 hosts
2024-07-11 20:15:22,772 - nornir.core.task -    ERROR -      start() - Host 'router': task 'netmiko_send_command' failed with traceback:
Traceback (most recent call last):
  File "/home/aibix/streams/vyos5/.abx-vyos5/lib/python3.11/site-packages/nornir/core/task.py", line 99, in start
    r = self.task(self, **self.params)
        ^^^^^^^^^^^^^^^^^^^^^^^^^^^^^^
  File "/home/aibix/streams/vyos5/.abx-vyos5/lib/python3.11/site-packages/nornir_netmiko/tasks/netmiko_send_command.py", line 26, in netmiko_send_command
    net_connect = task.host.get_connection(CONNECTION_NAME, task.nornir.config)
                  ^^^^^^^^^^^^^^^^^^^^^^^^^^^^^^^^^^^^^^^^^^^^^^^^^^^^^^^^^^^^^
  File "/home/aibix/streams/vyos5/.abx-vyos5/lib/python3.11/site-packages/nornir/core/inventory.py", line 494, in get_connection
    self.open_connection(
  File "/home/aibix/streams/vyos5/.abx-vyos5/lib/python3.11/site-packages/nornir/core/inventory.py", line 546, in open_connection
    conn_obj.open(
  File "/home/aibix/streams/vyos5/.abx-vyos5/lib/python3.11/site-packages/nornir_netmiko/connections/netmiko.py", line 59, in open
    connection = ConnectHandler(**parameters)
                 ^^^^^^^^^^^^^^^^^^^^^^^^^^^^
  File "/home/aibix/streams/vyos5/.abx-vyos5/lib/python3.11/site-packages/netmiko/ssh_dispatcher.py", line 390, in ConnectHandler
    device_type = kwargs["device_type"]
                  ~~~~~~^^^^^^^^^^^^^^^
KeyError: 'device_type'

2024-07-11 20:15:22,772 - nornir.core.task -    ERROR -      start() - Host 'router': task 'fetch_vyos_config' failed with traceback:
Traceback (most recent call last):
  File "/home/aibix/streams/vyos5/.abx-vyos5/lib/python3.11/site-packages/nornir/core/task.py", line 99, in start
    r = self.task(self, **self.params)
        ^^^^^^^^^^^^^^^^^^^^^^^^^^^^^^
  File "/home/aibix/streams/vyos5/fetch_config.py", line 41, in fetch_vyos_config
    config_result = task.run(
                    ^^^^^^^^^
  File "/home/aibix/streams/vyos5/.abx-vyos5/lib/python3.11/site-packages/nornir/core/task.py", line 174, in run
    raise NornirSubTaskError(task=run_task, result=r)
nornir.core.exceptions.NornirSubTaskError: Subtask: netmiko_send_command (failed)


2024-07-11 20:16:32,949 -  nornir.core -     INFO -        run() - Running task 'fetch_vyos_config' with args {} on 1 hosts
2024-07-11 20:16:32,951 - nornir.core.task -    ERROR -      start() - Host 'router': task 'netmiko_send_command' failed with traceback:
Traceback (most recent call last):
  File "/home/aibix/streams/vyos5/.abx-vyos5/lib/python3.11/site-packages/nornir/core/task.py", line 99, in start
    r = self.task(self, **self.params)
        ^^^^^^^^^^^^^^^^^^^^^^^^^^^^^^
  File "/home/aibix/streams/vyos5/.abx-vyos5/lib/python3.11/site-packages/nornir_netmiko/tasks/netmiko_send_command.py", line 26, in netmiko_send_command
    net_connect = task.host.get_connection(CONNECTION_NAME, task.nornir.config)
                  ^^^^^^^^^^^^^^^^^^^^^^^^^^^^^^^^^^^^^^^^^^^^^^^^^^^^^^^^^^^^^
  File "/home/aibix/streams/vyos5/.abx-vyos5/lib/python3.11/site-packages/nornir/core/inventory.py", line 494, in get_connection
    self.open_connection(
  File "/home/aibix/streams/vyos5/.abx-vyos5/lib/python3.11/site-packages/nornir/core/inventory.py", line 546, in open_connection
    conn_obj.open(
  File "/home/aibix/streams/vyos5/.abx-vyos5/lib/python3.11/site-packages/nornir_netmiko/connections/netmiko.py", line 59, in open
    connection = ConnectHandler(**parameters)
                 ^^^^^^^^^^^^^^^^^^^^^^^^^^^^
  File "/home/aibix/streams/vyos5/.abx-vyos5/lib/python3.11/site-packages/netmiko/ssh_dispatcher.py", line 390, in ConnectHandler
    device_type = kwargs["device_type"]
                  ~~~~~~^^^^^^^^^^^^^^^
KeyError: 'device_type'

2024-07-11 20:16:32,952 - nornir.core.task -    ERROR -      start() - Host 'router': task 'fetch_vyos_config' failed with traceback:
Traceback (most recent call last):
  File "/home/aibix/streams/vyos5/.abx-vyos5/lib/python3.11/site-packages/nornir/core/task.py", line 99, in start
    r = self.task(self, **self.params)
        ^^^^^^^^^^^^^^^^^^^^^^^^^^^^^^
  File "/home/aibix/streams/vyos5/fetch_config.py", line 41, in fetch_vyos_config
    config_result = task.run(
                    ^^^^^^^^^
  File "/home/aibix/streams/vyos5/.abx-vyos5/lib/python3.11/site-packages/nornir/core/task.py", line 174, in run
    raise NornirSubTaskError(task=run_task, result=r)
nornir.core.exceptions.NornirSubTaskError: Subtask: netmiko_send_command (failed)


2024-07-11 20:25:06,383 -  nornir.core -     INFO -        run() - Running task 'napalm_get' with args {'getters': ['config']} on 1 hosts
2024-07-11 20:25:06,386 - nornir.core.task -    ERROR -      start() - Host 'router': task 'napalm_get' failed with traceback:
Traceback (most recent call last):
  File "/home/aibix/streams/vyos5/.abx-vyos5/lib/python3.11/site-packages/nornir/core/task.py", line 99, in start
    r = self.task(self, **self.params)
        ^^^^^^^^^^^^^^^^^^^^^^^^^^^^^^
  File "/home/aibix/streams/vyos5/.abx-vyos5/lib/python3.11/site-packages/nornir_napalm/plugins/tasks/napalm_get.py", line 32, in napalm_get
    device = task.host.get_connection(CONNECTION_NAME, task.nornir.config)
             ^^^^^^^^^^^^^^^^^^^^^^^^^^^^^^^^^^^^^^^^^^^^^^^^^^^^^^^^^^^^^
  File "/home/aibix/streams/vyos5/.abx-vyos5/lib/python3.11/site-packages/nornir/core/inventory.py", line 494, in get_connection
    self.open_connection(
  File "/home/aibix/streams/vyos5/.abx-vyos5/lib/python3.11/site-packages/nornir/core/inventory.py", line 546, in open_connection
    conn_obj.open(
  File "/home/aibix/streams/vyos5/.abx-vyos5/lib/python3.11/site-packages/nornir_napalm/plugins/connections/__init__.py", line 55, in open
    network_driver = get_network_driver(platform)
                     ^^^^^^^^^^^^^^^^^^^^^^^^^^^^
  File "/home/aibix/streams/vyos5/.abx-vyos5/lib/python3.11/site-packages/napalm/base/__init__.py", line 70, in get_network_driver
    raise ModuleImportError("Please provide a valid driver name.")
napalm.base.exceptions.ModuleImportError: Please provide a valid driver name.

2024-07-11 20:25:48,808 -  nornir.core -     INFO -        run() - Running task 'napalm_get' with args {'getters': ['config']} on 1 hosts
2024-07-11 20:25:48,809 - nornir.core.task -    ERROR -      start() - Host 'router': task 'napalm_get' failed with traceback:
Traceback (most recent call last):
  File "/home/aibix/streams/vyos5/.abx-vyos5/lib/python3.11/site-packages/nornir/core/task.py", line 99, in start
    r = self.task(self, **self.params)
        ^^^^^^^^^^^^^^^^^^^^^^^^^^^^^^
  File "/home/aibix/streams/vyos5/.abx-vyos5/lib/python3.11/site-packages/nornir_napalm/plugins/tasks/napalm_get.py", line 32, in napalm_get
    device = task.host.get_connection(CONNECTION_NAME, task.nornir.config)
             ^^^^^^^^^^^^^^^^^^^^^^^^^^^^^^^^^^^^^^^^^^^^^^^^^^^^^^^^^^^^^
  File "/home/aibix/streams/vyos5/.abx-vyos5/lib/python3.11/site-packages/nornir/core/inventory.py", line 494, in get_connection
    self.open_connection(
  File "/home/aibix/streams/vyos5/.abx-vyos5/lib/python3.11/site-packages/nornir/core/inventory.py", line 546, in open_connection
    conn_obj.open(
  File "/home/aibix/streams/vyos5/.abx-vyos5/lib/python3.11/site-packages/nornir_napalm/plugins/connections/__init__.py", line 55, in open
    network_driver = get_network_driver(platform)
                     ^^^^^^^^^^^^^^^^^^^^^^^^^^^^
  File "/home/aibix/streams/vyos5/.abx-vyos5/lib/python3.11/site-packages/napalm/base/__init__.py", line 70, in get_network_driver
    raise ModuleImportError("Please provide a valid driver name.")
napalm.base.exceptions.ModuleImportError: Please provide a valid driver name.

2024-07-11 20:26:25,935 -  nornir.core -     INFO -        run() - Running task 'napalm_get' with args {'getters': ['config']} on 1 hosts
2024-07-11 20:26:25,936 - nornir.core.task -    ERROR -      start() - Host 'router': task 'napalm_get' failed with traceback:
Traceback (most recent call last):
  File "/home/aibix/streams/vyos5/.abx-vyos5/lib/python3.11/site-packages/nornir/core/task.py", line 99, in start
    r = self.task(self, **self.params)
        ^^^^^^^^^^^^^^^^^^^^^^^^^^^^^^
  File "/home/aibix/streams/vyos5/.abx-vyos5/lib/python3.11/site-packages/nornir_napalm/plugins/tasks/napalm_get.py", line 32, in napalm_get
    device = task.host.get_connection(CONNECTION_NAME, task.nornir.config)
             ^^^^^^^^^^^^^^^^^^^^^^^^^^^^^^^^^^^^^^^^^^^^^^^^^^^^^^^^^^^^^
  File "/home/aibix/streams/vyos5/.abx-vyos5/lib/python3.11/site-packages/nornir/core/inventory.py", line 494, in get_connection
    self.open_connection(
  File "/home/aibix/streams/vyos5/.abx-vyos5/lib/python3.11/site-packages/nornir/core/inventory.py", line 546, in open_connection
    conn_obj.open(
  File "/home/aibix/streams/vyos5/.abx-vyos5/lib/python3.11/site-packages/nornir_napalm/plugins/connections/__init__.py", line 55, in open
    network_driver = get_network_driver(platform)
                     ^^^^^^^^^^^^^^^^^^^^^^^^^^^^
  File "/home/aibix/streams/vyos5/.abx-vyos5/lib/python3.11/site-packages/napalm/base/__init__.py", line 70, in get_network_driver
    raise ModuleImportError("Please provide a valid driver name.")
napalm.base.exceptions.ModuleImportError: Please provide a valid driver name.

2024-07-11 20:26:42,253 -  nornir.core -     INFO -        run() - Running task 'napalm_get' with args {'getters': ['config']} on 1 hosts
2024-07-11 20:26:42,255 - nornir.core.task -    ERROR -      start() - Host 'router': task 'napalm_get' failed with traceback:
Traceback (most recent call last):
  File "/home/aibix/streams/vyos5/.abx-vyos5/lib/python3.11/site-packages/nornir/core/task.py", line 99, in start
    r = self.task(self, **self.params)
        ^^^^^^^^^^^^^^^^^^^^^^^^^^^^^^
  File "/home/aibix/streams/vyos5/.abx-vyos5/lib/python3.11/site-packages/nornir_napalm/plugins/tasks/napalm_get.py", line 32, in napalm_get
    device = task.host.get_connection(CONNECTION_NAME, task.nornir.config)
             ^^^^^^^^^^^^^^^^^^^^^^^^^^^^^^^^^^^^^^^^^^^^^^^^^^^^^^^^^^^^^
  File "/home/aibix/streams/vyos5/.abx-vyos5/lib/python3.11/site-packages/nornir/core/inventory.py", line 494, in get_connection
    self.open_connection(
  File "/home/aibix/streams/vyos5/.abx-vyos5/lib/python3.11/site-packages/nornir/core/inventory.py", line 546, in open_connection
    conn_obj.open(
  File "/home/aibix/streams/vyos5/.abx-vyos5/lib/python3.11/site-packages/nornir_napalm/plugins/connections/__init__.py", line 55, in open
    network_driver = get_network_driver(platform)
                     ^^^^^^^^^^^^^^^^^^^^^^^^^^^^
  File "/home/aibix/streams/vyos5/.abx-vyos5/lib/python3.11/site-packages/napalm/base/__init__.py", line 70, in get_network_driver
    raise ModuleImportError("Please provide a valid driver name.")
napalm.base.exceptions.ModuleImportError: Please provide a valid driver name.

2024-07-11 20:29:11,866 -  nornir.core -     INFO -        run() - Running task 'napalm_get' with args {'getters': ['config']} on 1 hosts
2024-07-11 20:29:11,867 - nornir.core.task -    ERROR -      start() - Host 'router': task 'napalm_get' failed with traceback:
Traceback (most recent call last):
  File "/home/aibix/streams/vyos5/.abx-vyos5/lib/python3.11/site-packages/nornir/core/task.py", line 99, in start
    r = self.task(self, **self.params)
        ^^^^^^^^^^^^^^^^^^^^^^^^^^^^^^
  File "/home/aibix/streams/vyos5/.abx-vyos5/lib/python3.11/site-packages/nornir_napalm/plugins/tasks/napalm_get.py", line 32, in napalm_get
    device = task.host.get_connection(CONNECTION_NAME, task.nornir.config)
             ^^^^^^^^^^^^^^^^^^^^^^^^^^^^^^^^^^^^^^^^^^^^^^^^^^^^^^^^^^^^^
  File "/home/aibix/streams/vyos5/.abx-vyos5/lib/python3.11/site-packages/nornir/core/inventory.py", line 494, in get_connection
    self.open_connection(
  File "/home/aibix/streams/vyos5/.abx-vyos5/lib/python3.11/site-packages/nornir/core/inventory.py", line 546, in open_connection
    conn_obj.open(
  File "/home/aibix/streams/vyos5/.abx-vyos5/lib/python3.11/site-packages/nornir_napalm/plugins/connections/__init__.py", line 55, in open
    network_driver = get_network_driver(platform)
                     ^^^^^^^^^^^^^^^^^^^^^^^^^^^^
  File "/home/aibix/streams/vyos5/.abx-vyos5/lib/python3.11/site-packages/napalm/base/__init__.py", line 70, in get_network_driver
    raise ModuleImportError("Please provide a valid driver name.")
napalm.base.exceptions.ModuleImportError: Please provide a valid driver name.

2024-07-11 20:29:30,281 -  nornir.core -     INFO -        run() - Running task 'napalm_get' with args {'getters': ['config']} on 1 hosts
2024-07-11 20:29:30,282 - nornir.core.task -    ERROR -      start() - Host 'router': task 'napalm_get' failed with traceback:
Traceback (most recent call last):
  File "/home/aibix/streams/vyos5/.abx-vyos5/lib/python3.11/site-packages/nornir/core/task.py", line 99, in start
    r = self.task(self, **self.params)
        ^^^^^^^^^^^^^^^^^^^^^^^^^^^^^^
  File "/home/aibix/streams/vyos5/.abx-vyos5/lib/python3.11/site-packages/nornir_napalm/plugins/tasks/napalm_get.py", line 32, in napalm_get
    device = task.host.get_connection(CONNECTION_NAME, task.nornir.config)
             ^^^^^^^^^^^^^^^^^^^^^^^^^^^^^^^^^^^^^^^^^^^^^^^^^^^^^^^^^^^^^
  File "/home/aibix/streams/vyos5/.abx-vyos5/lib/python3.11/site-packages/nornir/core/inventory.py", line 494, in get_connection
    self.open_connection(
  File "/home/aibix/streams/vyos5/.abx-vyos5/lib/python3.11/site-packages/nornir/core/inventory.py", line 546, in open_connection
    conn_obj.open(
  File "/home/aibix/streams/vyos5/.abx-vyos5/lib/python3.11/site-packages/nornir_napalm/plugins/connections/__init__.py", line 55, in open
    network_driver = get_network_driver(platform)
                     ^^^^^^^^^^^^^^^^^^^^^^^^^^^^
  File "/home/aibix/streams/vyos5/.abx-vyos5/lib/python3.11/site-packages/napalm/base/__init__.py", line 70, in get_network_driver
    raise ModuleImportError("Please provide a valid driver name.")
napalm.base.exceptions.ModuleImportError: Please provide a valid driver name.

2024-07-11 20:40:15,319 -  nornir.core -     INFO -        run() - Running task 'napalm_get' with args {'getters': ['config']} on 1 hosts
2024-07-11 20:40:15,322 - nornir.core.task -    ERROR -      start() - Host 'router': task 'napalm_get' failed with traceback:
Traceback (most recent call last):
  File "/home/aibix/streams/vyos5/.abx-vyos5/lib/python3.11/site-packages/nornir/core/task.py", line 99, in start
    r = self.task(self, **self.params)
        ^^^^^^^^^^^^^^^^^^^^^^^^^^^^^^
  File "/home/aibix/streams/vyos5/.abx-vyos5/lib/python3.11/site-packages/nornir_napalm/plugins/tasks/napalm_get.py", line 32, in napalm_get
    device = task.host.get_connection(CONNECTION_NAME, task.nornir.config)
             ^^^^^^^^^^^^^^^^^^^^^^^^^^^^^^^^^^^^^^^^^^^^^^^^^^^^^^^^^^^^^
  File "/home/aibix/streams/vyos5/.abx-vyos5/lib/python3.11/site-packages/nornir/core/inventory.py", line 494, in get_connection
    self.open_connection(
  File "/home/aibix/streams/vyos5/.abx-vyos5/lib/python3.11/site-packages/nornir/core/inventory.py", line 546, in open_connection
    conn_obj.open(
  File "/home/aibix/streams/vyos5/.abx-vyos5/lib/python3.11/site-packages/nornir_napalm/plugins/connections/__init__.py", line 55, in open
    network_driver = get_network_driver(platform)
                     ^^^^^^^^^^^^^^^^^^^^^^^^^^^^
  File "/home/aibix/streams/vyos5/.abx-vyos5/lib/python3.11/site-packages/napalm/base/__init__.py", line 70, in get_network_driver
    raise ModuleImportError("Please provide a valid driver name.")
napalm.base.exceptions.ModuleImportError: Please provide a valid driver name.

2024-07-11 20:40:29,448 -  nornir.core -     INFO -        run() - Running task 'napalm_get' with args {'getters': ['config']} on 1 hosts
2024-07-11 20:40:29,450 - nornir.core.task -    ERROR -      start() - Host 'router': task 'napalm_get' failed with traceback:
Traceback (most recent call last):
  File "/home/aibix/streams/vyos5/.abx-vyos5/lib/python3.11/site-packages/nornir/core/task.py", line 99, in start
    r = self.task(self, **self.params)
        ^^^^^^^^^^^^^^^^^^^^^^^^^^^^^^
  File "/home/aibix/streams/vyos5/.abx-vyos5/lib/python3.11/site-packages/nornir_napalm/plugins/tasks/napalm_get.py", line 32, in napalm_get
    device = task.host.get_connection(CONNECTION_NAME, task.nornir.config)
             ^^^^^^^^^^^^^^^^^^^^^^^^^^^^^^^^^^^^^^^^^^^^^^^^^^^^^^^^^^^^^
  File "/home/aibix/streams/vyos5/.abx-vyos5/lib/python3.11/site-packages/nornir/core/inventory.py", line 494, in get_connection
    self.open_connection(
  File "/home/aibix/streams/vyos5/.abx-vyos5/lib/python3.11/site-packages/nornir/core/inventory.py", line 546, in open_connection
    conn_obj.open(
  File "/home/aibix/streams/vyos5/.abx-vyos5/lib/python3.11/site-packages/nornir_napalm/plugins/connections/__init__.py", line 55, in open
    network_driver = get_network_driver(platform)
                     ^^^^^^^^^^^^^^^^^^^^^^^^^^^^
  File "/home/aibix/streams/vyos5/.abx-vyos5/lib/python3.11/site-packages/napalm/base/__init__.py", line 70, in get_network_driver
    raise ModuleImportError("Please provide a valid driver name.")
napalm.base.exceptions.ModuleImportError: Please provide a valid driver name.

2024-07-11 20:41:29,304 -  nornir.core -     INFO -        run() - Running task 'napalm_get' with args {'getters': ['config']} on 1 hosts
2024-07-11 20:41:29,305 - nornir.core.task -    ERROR -      start() - Host 'router': task 'napalm_get' failed with traceback:
Traceback (most recent call last):
  File "/home/aibix/streams/vyos5/.abx-vyos5/lib/python3.11/site-packages/nornir/core/task.py", line 99, in start
    r = self.task(self, **self.params)
        ^^^^^^^^^^^^^^^^^^^^^^^^^^^^^^
  File "/home/aibix/streams/vyos5/.abx-vyos5/lib/python3.11/site-packages/nornir_napalm/plugins/tasks/napalm_get.py", line 32, in napalm_get
    device = task.host.get_connection(CONNECTION_NAME, task.nornir.config)
             ^^^^^^^^^^^^^^^^^^^^^^^^^^^^^^^^^^^^^^^^^^^^^^^^^^^^^^^^^^^^^
  File "/home/aibix/streams/vyos5/.abx-vyos5/lib/python3.11/site-packages/nornir/core/inventory.py", line 494, in get_connection
    self.open_connection(
  File "/home/aibix/streams/vyos5/.abx-vyos5/lib/python3.11/site-packages/nornir/core/inventory.py", line 546, in open_connection
    conn_obj.open(
  File "/home/aibix/streams/vyos5/.abx-vyos5/lib/python3.11/site-packages/nornir_napalm/plugins/connections/__init__.py", line 55, in open
    network_driver = get_network_driver(platform)
                     ^^^^^^^^^^^^^^^^^^^^^^^^^^^^
  File "/home/aibix/streams/vyos5/.abx-vyos5/lib/python3.11/site-packages/napalm/base/__init__.py", line 70, in get_network_driver
    raise ModuleImportError("Please provide a valid driver name.")
napalm.base.exceptions.ModuleImportError: Please provide a valid driver name.

2024-07-11 20:43:29,176 -  nornir.core -     INFO -        run() - Running task 'napalm_get' with args {'getters': ['config']} on 1 hosts
2024-07-11 20:43:29,179 - nornir.core.task -    ERROR -      start() - Host 'router': task 'napalm_get' failed with traceback:
Traceback (most recent call last):
  File "/home/aibix/streams/vyos5/.abx-vyos5/lib/python3.11/site-packages/nornir/core/task.py", line 99, in start
    r = self.task(self, **self.params)
        ^^^^^^^^^^^^^^^^^^^^^^^^^^^^^^
  File "/home/aibix/streams/vyos5/.abx-vyos5/lib/python3.11/site-packages/nornir_napalm/plugins/tasks/napalm_get.py", line 32, in napalm_get
    device = task.host.get_connection(CONNECTION_NAME, task.nornir.config)
             ^^^^^^^^^^^^^^^^^^^^^^^^^^^^^^^^^^^^^^^^^^^^^^^^^^^^^^^^^^^^^
  File "/home/aibix/streams/vyos5/.abx-vyos5/lib/python3.11/site-packages/nornir/core/inventory.py", line 494, in get_connection
    self.open_connection(
  File "/home/aibix/streams/vyos5/.abx-vyos5/lib/python3.11/site-packages/nornir/core/inventory.py", line 546, in open_connection
    conn_obj.open(
  File "/home/aibix/streams/vyos5/.abx-vyos5/lib/python3.11/site-packages/nornir_napalm/plugins/connections/__init__.py", line 55, in open
    network_driver = get_network_driver(platform)
                     ^^^^^^^^^^^^^^^^^^^^^^^^^^^^
  File "/home/aibix/streams/vyos5/.abx-vyos5/lib/python3.11/site-packages/napalm/base/__init__.py", line 70, in get_network_driver
    raise ModuleImportError("Please provide a valid driver name.")
napalm.base.exceptions.ModuleImportError: Please provide a valid driver name.

2024-07-11 20:44:43,235 -  nornir.core -     INFO -        run() - Running task 'napalm_get' with args {'getters': ['config']} on 1 hosts
2024-07-11 20:44:43,238 - nornir.core.task -    ERROR -      start() - Host 'router': task 'napalm_get' failed with traceback:
Traceback (most recent call last):
  File "/home/aibix/streams/vyos5/.abx-vyos5/lib/python3.11/site-packages/nornir/core/task.py", line 99, in start
    r = self.task(self, **self.params)
        ^^^^^^^^^^^^^^^^^^^^^^^^^^^^^^
  File "/home/aibix/streams/vyos5/.abx-vyos5/lib/python3.11/site-packages/nornir_napalm/plugins/tasks/napalm_get.py", line 32, in napalm_get
    device = task.host.get_connection(CONNECTION_NAME, task.nornir.config)
             ^^^^^^^^^^^^^^^^^^^^^^^^^^^^^^^^^^^^^^^^^^^^^^^^^^^^^^^^^^^^^
  File "/home/aibix/streams/vyos5/.abx-vyos5/lib/python3.11/site-packages/nornir/core/inventory.py", line 494, in get_connection
    self.open_connection(
  File "/home/aibix/streams/vyos5/.abx-vyos5/lib/python3.11/site-packages/nornir/core/inventory.py", line 546, in open_connection
    conn_obj.open(
  File "/home/aibix/streams/vyos5/.abx-vyos5/lib/python3.11/site-packages/nornir_napalm/plugins/connections/__init__.py", line 55, in open
    network_driver = get_network_driver(platform)
                     ^^^^^^^^^^^^^^^^^^^^^^^^^^^^
  File "/home/aibix/streams/vyos5/.abx-vyos5/lib/python3.11/site-packages/napalm/base/__init__.py", line 70, in get_network_driver
    raise ModuleImportError("Please provide a valid driver name.")
napalm.base.exceptions.ModuleImportError: Please provide a valid driver name.

2024-07-11 20:45:25,033 -  nornir.core -     INFO -        run() - Running task 'napalm_get' with args {'getters': ['config']} on 1 hosts
2024-07-11 20:45:25,035 - nornir.core.task -    ERROR -      start() - Host 'router': task 'napalm_get' failed with traceback:
Traceback (most recent call last):
  File "/home/aibix/streams/vyos5/.abx-vyos5/lib/python3.11/site-packages/nornir/core/task.py", line 99, in start
    r = self.task(self, **self.params)
        ^^^^^^^^^^^^^^^^^^^^^^^^^^^^^^
  File "/home/aibix/streams/vyos5/.abx-vyos5/lib/python3.11/site-packages/nornir_napalm/plugins/tasks/napalm_get.py", line 32, in napalm_get
    device = task.host.get_connection(CONNECTION_NAME, task.nornir.config)
             ^^^^^^^^^^^^^^^^^^^^^^^^^^^^^^^^^^^^^^^^^^^^^^^^^^^^^^^^^^^^^
  File "/home/aibix/streams/vyos5/.abx-vyos5/lib/python3.11/site-packages/nornir/core/inventory.py", line 494, in get_connection
    self.open_connection(
  File "/home/aibix/streams/vyos5/.abx-vyos5/lib/python3.11/site-packages/nornir/core/inventory.py", line 546, in open_connection
    conn_obj.open(
  File "/home/aibix/streams/vyos5/.abx-vyos5/lib/python3.11/site-packages/nornir_napalm/plugins/connections/__init__.py", line 55, in open
    network_driver = get_network_driver(platform)
                     ^^^^^^^^^^^^^^^^^^^^^^^^^^^^
  File "/home/aibix/streams/vyos5/.abx-vyos5/lib/python3.11/site-packages/napalm/base/__init__.py", line 70, in get_network_driver
    raise ModuleImportError("Please provide a valid driver name.")
napalm.base.exceptions.ModuleImportError: Please provide a valid driver name.

2024-07-11 20:47:20,005 -  nornir.core -     INFO -        run() - Running task 'napalm_get' with args {'getters': ['config']} on 1 hosts
2024-07-11 20:47:20,007 - nornir.core.task -    ERROR -      start() - Host 'router': task 'napalm_get' failed with traceback:
Traceback (most recent call last):
  File "/home/aibix/streams/vyos5/.abx-vyos5/lib/python3.11/site-packages/nornir/core/task.py", line 99, in start
    r = self.task(self, **self.params)
        ^^^^^^^^^^^^^^^^^^^^^^^^^^^^^^
  File "/home/aibix/streams/vyos5/.abx-vyos5/lib/python3.11/site-packages/nornir_napalm/plugins/tasks/napalm_get.py", line 32, in napalm_get
    device = task.host.get_connection(CONNECTION_NAME, task.nornir.config)
             ^^^^^^^^^^^^^^^^^^^^^^^^^^^^^^^^^^^^^^^^^^^^^^^^^^^^^^^^^^^^^
  File "/home/aibix/streams/vyos5/.abx-vyos5/lib/python3.11/site-packages/nornir/core/inventory.py", line 494, in get_connection
    self.open_connection(
  File "/home/aibix/streams/vyos5/.abx-vyos5/lib/python3.11/site-packages/nornir/core/inventory.py", line 546, in open_connection
    conn_obj.open(
  File "/home/aibix/streams/vyos5/.abx-vyos5/lib/python3.11/site-packages/nornir_napalm/plugins/connections/__init__.py", line 55, in open
    network_driver = get_network_driver(platform)
                     ^^^^^^^^^^^^^^^^^^^^^^^^^^^^
  File "/home/aibix/streams/vyos5/.abx-vyos5/lib/python3.11/site-packages/napalm/base/__init__.py", line 70, in get_network_driver
    raise ModuleImportError("Please provide a valid driver name.")
napalm.base.exceptions.ModuleImportError: Please provide a valid driver name.

2024-07-11 20:49:27,824 -  nornir.core -     INFO -        run() - Running task 'napalm_get' with args {'getters': ['config']} on 1 hosts
2024-07-11 20:49:27,826 - nornir.core.task -    ERROR -      start() - Host 'router': task 'napalm_get' failed with traceback:
Traceback (most recent call last):
  File "/home/aibix/streams/vyos5/.abx-vyos5/lib/python3.11/site-packages/nornir/core/task.py", line 99, in start
    r = self.task(self, **self.params)
        ^^^^^^^^^^^^^^^^^^^^^^^^^^^^^^
  File "/home/aibix/streams/vyos5/.abx-vyos5/lib/python3.11/site-packages/nornir_napalm/plugins/tasks/napalm_get.py", line 32, in napalm_get
    device = task.host.get_connection(CONNECTION_NAME, task.nornir.config)
             ^^^^^^^^^^^^^^^^^^^^^^^^^^^^^^^^^^^^^^^^^^^^^^^^^^^^^^^^^^^^^
  File "/home/aibix/streams/vyos5/.abx-vyos5/lib/python3.11/site-packages/nornir/core/inventory.py", line 494, in get_connection
    self.open_connection(
  File "/home/aibix/streams/vyos5/.abx-vyos5/lib/python3.11/site-packages/nornir/core/inventory.py", line 546, in open_connection
    conn_obj.open(
  File "/home/aibix/streams/vyos5/.abx-vyos5/lib/python3.11/site-packages/nornir_napalm/plugins/connections/__init__.py", line 55, in open
    network_driver = get_network_driver(platform)
                     ^^^^^^^^^^^^^^^^^^^^^^^^^^^^
  File "/home/aibix/streams/vyos5/.abx-vyos5/lib/python3.11/site-packages/napalm/base/__init__.py", line 70, in get_network_driver
    raise ModuleImportError("Please provide a valid driver name.")
napalm.base.exceptions.ModuleImportError: Please provide a valid driver name.

2024-07-11 20:49:43,454 -  nornir.core -     INFO -        run() - Running task 'napalm_get' with args {'getters': ['config']} on 1 hosts
2024-07-11 20:49:43,457 - nornir.core.task -    ERROR -      start() - Host 'router': task 'napalm_get' failed with traceback:
Traceback (most recent call last):
  File "/home/aibix/streams/vyos5/.abx-vyos5/lib/python3.11/site-packages/nornir/core/task.py", line 99, in start
    r = self.task(self, **self.params)
        ^^^^^^^^^^^^^^^^^^^^^^^^^^^^^^
  File "/home/aibix/streams/vyos5/.abx-vyos5/lib/python3.11/site-packages/nornir_napalm/plugins/tasks/napalm_get.py", line 32, in napalm_get
    device = task.host.get_connection(CONNECTION_NAME, task.nornir.config)
             ^^^^^^^^^^^^^^^^^^^^^^^^^^^^^^^^^^^^^^^^^^^^^^^^^^^^^^^^^^^^^
  File "/home/aibix/streams/vyos5/.abx-vyos5/lib/python3.11/site-packages/nornir/core/inventory.py", line 494, in get_connection
    self.open_connection(
  File "/home/aibix/streams/vyos5/.abx-vyos5/lib/python3.11/site-packages/nornir/core/inventory.py", line 546, in open_connection
    conn_obj.open(
  File "/home/aibix/streams/vyos5/.abx-vyos5/lib/python3.11/site-packages/nornir_napalm/plugins/connections/__init__.py", line 55, in open
    network_driver = get_network_driver(platform)
                     ^^^^^^^^^^^^^^^^^^^^^^^^^^^^
  File "/home/aibix/streams/vyos5/.abx-vyos5/lib/python3.11/site-packages/napalm/base/__init__.py", line 70, in get_network_driver
    raise ModuleImportError("Please provide a valid driver name.")
napalm.base.exceptions.ModuleImportError: Please provide a valid driver name.

2024-07-11 20:49:54,183 -  nornir.core -     INFO -        run() - Running task 'napalm_get' with args {'getters': ['config']} on 1 hosts
2024-07-11 20:49:54,184 - nornir.core.task -    ERROR -      start() - Host 'router': task 'napalm_get' failed with traceback:
Traceback (most recent call last):
  File "/home/aibix/streams/vyos5/.abx-vyos5/lib/python3.11/site-packages/nornir/core/task.py", line 99, in start
    r = self.task(self, **self.params)
        ^^^^^^^^^^^^^^^^^^^^^^^^^^^^^^
  File "/home/aibix/streams/vyos5/.abx-vyos5/lib/python3.11/site-packages/nornir_napalm/plugins/tasks/napalm_get.py", line 32, in napalm_get
    device = task.host.get_connection(CONNECTION_NAME, task.nornir.config)
             ^^^^^^^^^^^^^^^^^^^^^^^^^^^^^^^^^^^^^^^^^^^^^^^^^^^^^^^^^^^^^
  File "/home/aibix/streams/vyos5/.abx-vyos5/lib/python3.11/site-packages/nornir/core/inventory.py", line 494, in get_connection
    self.open_connection(
  File "/home/aibix/streams/vyos5/.abx-vyos5/lib/python3.11/site-packages/nornir/core/inventory.py", line 546, in open_connection
    conn_obj.open(
  File "/home/aibix/streams/vyos5/.abx-vyos5/lib/python3.11/site-packages/nornir_napalm/plugins/connections/__init__.py", line 55, in open
    network_driver = get_network_driver(platform)
                     ^^^^^^^^^^^^^^^^^^^^^^^^^^^^
  File "/home/aibix/streams/vyos5/.abx-vyos5/lib/python3.11/site-packages/napalm/base/__init__.py", line 70, in get_network_driver
    raise ModuleImportError("Please provide a valid driver name.")
napalm.base.exceptions.ModuleImportError: Please provide a valid driver name.

2024-07-11 20:52:30,297 -  nornir.core -     INFO -        run() - Running task 'napalm_get' with args {'getters': ['config']} on 1 hosts
2024-07-11 20:52:30,300 - nornir.core.task -    ERROR -      start() - Host 'router': task 'napalm_get' failed with traceback:
Traceback (most recent call last):
  File "/home/aibix/streams/vyos5/.abx-vyos5/lib/python3.11/site-packages/nornir/core/task.py", line 99, in start
    r = self.task(self, **self.params)
        ^^^^^^^^^^^^^^^^^^^^^^^^^^^^^^
  File "/home/aibix/streams/vyos5/.abx-vyos5/lib/python3.11/site-packages/nornir_napalm/plugins/tasks/napalm_get.py", line 32, in napalm_get
    device = task.host.get_connection(CONNECTION_NAME, task.nornir.config)
             ^^^^^^^^^^^^^^^^^^^^^^^^^^^^^^^^^^^^^^^^^^^^^^^^^^^^^^^^^^^^^
  File "/home/aibix/streams/vyos5/.abx-vyos5/lib/python3.11/site-packages/nornir/core/inventory.py", line 494, in get_connection
    self.open_connection(
  File "/home/aibix/streams/vyos5/.abx-vyos5/lib/python3.11/site-packages/nornir/core/inventory.py", line 546, in open_connection
    conn_obj.open(
  File "/home/aibix/streams/vyos5/.abx-vyos5/lib/python3.11/site-packages/nornir_napalm/plugins/connections/__init__.py", line 55, in open
    network_driver = get_network_driver(platform)
                     ^^^^^^^^^^^^^^^^^^^^^^^^^^^^
  File "/home/aibix/streams/vyos5/.abx-vyos5/lib/python3.11/site-packages/napalm/base/__init__.py", line 70, in get_network_driver
    raise ModuleImportError("Please provide a valid driver name.")
napalm.base.exceptions.ModuleImportError: Please provide a valid driver name.

2024-07-11 20:53:21,391 -  nornir.core -     INFO -        run() - Running task 'napalm_get' with args {'getters': ['config']} on 1 hosts
2024-07-11 20:53:21,392 - nornir.core.task -    ERROR -      start() - Host 'router': task 'napalm_get' failed with traceback:
Traceback (most recent call last):
  File "/home/aibix/streams/vyos5/.abx-vyos5/lib/python3.11/site-packages/nornir/core/task.py", line 99, in start
    r = self.task(self, **self.params)
        ^^^^^^^^^^^^^^^^^^^^^^^^^^^^^^
  File "/home/aibix/streams/vyos5/.abx-vyos5/lib/python3.11/site-packages/nornir_napalm/plugins/tasks/napalm_get.py", line 32, in napalm_get
    device = task.host.get_connection(CONNECTION_NAME, task.nornir.config)
             ^^^^^^^^^^^^^^^^^^^^^^^^^^^^^^^^^^^^^^^^^^^^^^^^^^^^^^^^^^^^^
  File "/home/aibix/streams/vyos5/.abx-vyos5/lib/python3.11/site-packages/nornir/core/inventory.py", line 494, in get_connection
    self.open_connection(
  File "/home/aibix/streams/vyos5/.abx-vyos5/lib/python3.11/site-packages/nornir/core/inventory.py", line 546, in open_connection
    conn_obj.open(
  File "/home/aibix/streams/vyos5/.abx-vyos5/lib/python3.11/site-packages/nornir_napalm/plugins/connections/__init__.py", line 55, in open
    network_driver = get_network_driver(platform)
                     ^^^^^^^^^^^^^^^^^^^^^^^^^^^^
  File "/home/aibix/streams/vyos5/.abx-vyos5/lib/python3.11/site-packages/napalm/base/__init__.py", line 70, in get_network_driver
    raise ModuleImportError("Please provide a valid driver name.")
napalm.base.exceptions.ModuleImportError: Please provide a valid driver name.

2024-07-11 20:56:54,087 -  nornir.core -     INFO -        run() - Running task 'napalm_get' with args {'getters': ['config']} on 1 hosts
2024-07-11 20:56:54,089 - nornir.core.task -    ERROR -      start() - Host 'router': task 'napalm_get' failed with traceback:
Traceback (most recent call last):
  File "/home/aibix/streams/vyos5/.abx-vyos5/lib/python3.11/site-packages/nornir/core/task.py", line 99, in start
    r = self.task(self, **self.params)
        ^^^^^^^^^^^^^^^^^^^^^^^^^^^^^^
  File "/home/aibix/streams/vyos5/.abx-vyos5/lib/python3.11/site-packages/nornir_napalm/plugins/tasks/napalm_get.py", line 32, in napalm_get
    device = task.host.get_connection(CONNECTION_NAME, task.nornir.config)
             ^^^^^^^^^^^^^^^^^^^^^^^^^^^^^^^^^^^^^^^^^^^^^^^^^^^^^^^^^^^^^
  File "/home/aibix/streams/vyos5/.abx-vyos5/lib/python3.11/site-packages/nornir/core/inventory.py", line 494, in get_connection
    self.open_connection(
  File "/home/aibix/streams/vyos5/.abx-vyos5/lib/python3.11/site-packages/nornir/core/inventory.py", line 546, in open_connection
    conn_obj.open(
  File "/home/aibix/streams/vyos5/.abx-vyos5/lib/python3.11/site-packages/nornir_napalm/plugins/connections/__init__.py", line 55, in open
    network_driver = get_network_driver(platform)
                     ^^^^^^^^^^^^^^^^^^^^^^^^^^^^
  File "/home/aibix/streams/vyos5/.abx-vyos5/lib/python3.11/site-packages/napalm/base/__init__.py", line 70, in get_network_driver
    raise ModuleImportError("Please provide a valid driver name.")
napalm.base.exceptions.ModuleImportError: Please provide a valid driver name.

2024-07-11 20:58:27,281 -  nornir.core -     INFO -        run() - Running task 'napalm_get' with args {'getters': ['config']} on 1 hosts
2024-07-11 20:58:27,284 - nornir.core.task -    ERROR -      start() - Host 'router': task 'napalm_get' failed with traceback:
Traceback (most recent call last):
  File "/home/aibix/streams/vyos5/.abx-vyos5/lib/python3.11/site-packages/nornir/core/task.py", line 99, in start
    r = self.task(self, **self.params)
        ^^^^^^^^^^^^^^^^^^^^^^^^^^^^^^
  File "/home/aibix/streams/vyos5/.abx-vyos5/lib/python3.11/site-packages/nornir_napalm/plugins/tasks/napalm_get.py", line 32, in napalm_get
    device = task.host.get_connection(CONNECTION_NAME, task.nornir.config)
             ^^^^^^^^^^^^^^^^^^^^^^^^^^^^^^^^^^^^^^^^^^^^^^^^^^^^^^^^^^^^^
  File "/home/aibix/streams/vyos5/.abx-vyos5/lib/python3.11/site-packages/nornir/core/inventory.py", line 494, in get_connection
    self.open_connection(
  File "/home/aibix/streams/vyos5/.abx-vyos5/lib/python3.11/site-packages/nornir/core/inventory.py", line 546, in open_connection
    conn_obj.open(
  File "/home/aibix/streams/vyos5/.abx-vyos5/lib/python3.11/site-packages/nornir_napalm/plugins/connections/__init__.py", line 55, in open
    network_driver = get_network_driver(platform)
                     ^^^^^^^^^^^^^^^^^^^^^^^^^^^^
  File "/home/aibix/streams/vyos5/.abx-vyos5/lib/python3.11/site-packages/napalm/base/__init__.py", line 70, in get_network_driver
    raise ModuleImportError("Please provide a valid driver name.")
napalm.base.exceptions.ModuleImportError: Please provide a valid driver name.

2024-07-11 21:06:54,241 -  nornir.core -     INFO -        run() - Running task 'napalm_get' with args {'getters': ['config']} on 1 hosts
2024-07-11 21:06:54,243 - nornir.core.task -    ERROR -      start() - Host 'router': task 'napalm_get' failed with traceback:
Traceback (most recent call last):
  File "/home/aibix/streams/vyos5/.abx-vyos5/lib/python3.11/site-packages/nornir/core/task.py", line 99, in start
    r = self.task(self, **self.params)
        ^^^^^^^^^^^^^^^^^^^^^^^^^^^^^^
  File "/home/aibix/streams/vyos5/.abx-vyos5/lib/python3.11/site-packages/nornir_napalm/plugins/tasks/napalm_get.py", line 32, in napalm_get
    device = task.host.get_connection(CONNECTION_NAME, task.nornir.config)
             ^^^^^^^^^^^^^^^^^^^^^^^^^^^^^^^^^^^^^^^^^^^^^^^^^^^^^^^^^^^^^
  File "/home/aibix/streams/vyos5/.abx-vyos5/lib/python3.11/site-packages/nornir/core/inventory.py", line 494, in get_connection
    self.open_connection(
  File "/home/aibix/streams/vyos5/.abx-vyos5/lib/python3.11/site-packages/nornir/core/inventory.py", line 546, in open_connection
    conn_obj.open(
  File "/home/aibix/streams/vyos5/.abx-vyos5/lib/python3.11/site-packages/nornir_napalm/plugins/connections/__init__.py", line 55, in open
    network_driver = get_network_driver(platform)
                     ^^^^^^^^^^^^^^^^^^^^^^^^^^^^
  File "/home/aibix/streams/vyos5/.abx-vyos5/lib/python3.11/site-packages/napalm/base/__init__.py", line 70, in get_network_driver
    raise ModuleImportError("Please provide a valid driver name.")
napalm.base.exceptions.ModuleImportError: Please provide a valid driver name.

2024-07-11 21:08:53,216 -  nornir.core -     INFO -        run() - Running task 'napalm_get' with args {'getters': ['config']} on 1 hosts
2024-07-11 21:12:20,860 -  nornir.core -     INFO -        run() - Running task 'napalm_get' with args {'getters': ['config']} on 1 hosts
2024-07-11 21:12:20,863 - nornir.core.task -    ERROR -      start() - Host 'router': task 'napalm_get' failed with traceback:
Traceback (most recent call last):
  File "/home/aibix/streams/vyos5/.abx-vyos5/lib/python3.11/site-packages/nornir/core/task.py", line 99, in start
    r = self.task(self, **self.params)
        ^^^^^^^^^^^^^^^^^^^^^^^^^^^^^^
  File "/home/aibix/streams/vyos5/.abx-vyos5/lib/python3.11/site-packages/nornir_napalm/plugins/tasks/napalm_get.py", line 32, in napalm_get
    device = task.host.get_connection(CONNECTION_NAME, task.nornir.config)
             ^^^^^^^^^^^^^^^^^^^^^^^^^^^^^^^^^^^^^^^^^^^^^^^^^^^^^^^^^^^^^
  File "/home/aibix/streams/vyos5/.abx-vyos5/lib/python3.11/site-packages/nornir/core/inventory.py", line 494, in get_connection
    self.open_connection(
  File "/home/aibix/streams/vyos5/.abx-vyos5/lib/python3.11/site-packages/nornir/core/inventory.py", line 546, in open_connection
    conn_obj.open(
  File "/home/aibix/streams/vyos5/.abx-vyos5/lib/python3.11/site-packages/nornir_napalm/plugins/connections/__init__.py", line 55, in open
    network_driver = get_network_driver(platform)
                     ^^^^^^^^^^^^^^^^^^^^^^^^^^^^
  File "/home/aibix/streams/vyos5/.abx-vyos5/lib/python3.11/site-packages/napalm/base/__init__.py", line 70, in get_network_driver
    raise ModuleImportError("Please provide a valid driver name.")
napalm.base.exceptions.ModuleImportError: Please provide a valid driver name.

2024-07-11 21:13:16,274 -  nornir.core -     INFO -        run() - Running task 'napalm_get' with args {'getters': ['config']} on 8 hosts
2024-07-11 21:15:54,018 -  nornir.core -     INFO -        run() - Running task 'napalm_get' with args {'getters': ['config']} on 8 hosts
2024-07-11 21:23:04,129 -  nornir.core -     INFO -        run() - Running task 'fetch_vyos_config' with args {} on 8 hosts
2024-07-11 21:23:08,692 - nornir.core.task -    ERROR -      start() - Host 'p2r6v': task 'fetch_vyos_config' failed with traceback:
Traceback (most recent call last):
  File "/home/aibix/streams/vyos5/.abx-vyos5/lib/python3.11/site-packages/nornir/core/task.py", line 99, in start
    r = self.task(self, **self.params)
        ^^^^^^^^^^^^^^^^^^^^^^^^^^^^^^
  File "/home/aibix/streams/vyos5/fetch_config.py", line 23, in fetch_vyos_config
    task=nautobot_create_device,
         ^^^^^^^^^^^^^^^^^^^^^^
NameError: name 'nautobot_create_device' is not defined

2024-07-11 21:23:08,725 - nornir.core.task -    ERROR -      start() - Host 'p2r3v': task 'fetch_vyos_config' failed with traceback:
Traceback (most recent call last):
  File "/home/aibix/streams/vyos5/.abx-vyos5/lib/python3.11/site-packages/nornir/core/task.py", line 99, in start
    r = self.task(self, **self.params)
        ^^^^^^^^^^^^^^^^^^^^^^^^^^^^^^
  File "/home/aibix/streams/vyos5/fetch_config.py", line 23, in fetch_vyos_config
    task=nautobot_create_device,
         ^^^^^^^^^^^^^^^^^^^^^^
NameError: name 'nautobot_create_device' is not defined

2024-07-11 21:23:08,777 - nornir.core.task -    ERROR -      start() - Host 'p2r5v': task 'fetch_vyos_config' failed with traceback:
Traceback (most recent call last):
  File "/home/aibix/streams/vyos5/.abx-vyos5/lib/python3.11/site-packages/nornir/core/task.py", line 99, in start
    r = self.task(self, **self.params)
        ^^^^^^^^^^^^^^^^^^^^^^^^^^^^^^
  File "/home/aibix/streams/vyos5/fetch_config.py", line 23, in fetch_vyos_config
    task=nautobot_create_device,
         ^^^^^^^^^^^^^^^^^^^^^^
NameError: name 'nautobot_create_device' is not defined

2024-07-11 21:23:08,854 - nornir.core.task -    ERROR -      start() - Host 'p2r8v': task 'fetch_vyos_config' failed with traceback:
Traceback (most recent call last):
  File "/home/aibix/streams/vyos5/.abx-vyos5/lib/python3.11/site-packages/nornir/core/task.py", line 99, in start
    r = self.task(self, **self.params)
        ^^^^^^^^^^^^^^^^^^^^^^^^^^^^^^
  File "/home/aibix/streams/vyos5/fetch_config.py", line 23, in fetch_vyos_config
    task=nautobot_create_device,
         ^^^^^^^^^^^^^^^^^^^^^^
NameError: name 'nautobot_create_device' is not defined

2024-07-11 21:23:09,366 - nornir.core.task -    ERROR -      start() - Host 'p2r1v': task 'fetch_vyos_config' failed with traceback:
Traceback (most recent call last):
  File "/home/aibix/streams/vyos5/.abx-vyos5/lib/python3.11/site-packages/nornir/core/task.py", line 99, in start
    r = self.task(self, **self.params)
        ^^^^^^^^^^^^^^^^^^^^^^^^^^^^^^
  File "/home/aibix/streams/vyos5/fetch_config.py", line 23, in fetch_vyos_config
    task=nautobot_create_device,
         ^^^^^^^^^^^^^^^^^^^^^^
NameError: name 'nautobot_create_device' is not defined

2024-07-11 21:23:09,647 - nornir.core.task -    ERROR -      start() - Host 'p2r2v': task 'fetch_vyos_config' failed with traceback:
Traceback (most recent call last):
  File "/home/aibix/streams/vyos5/.abx-vyos5/lib/python3.11/site-packages/nornir/core/task.py", line 99, in start
    r = self.task(self, **self.params)
        ^^^^^^^^^^^^^^^^^^^^^^^^^^^^^^
  File "/home/aibix/streams/vyos5/fetch_config.py", line 23, in fetch_vyos_config
    task=nautobot_create_device,
         ^^^^^^^^^^^^^^^^^^^^^^
NameError: name 'nautobot_create_device' is not defined

2024-07-11 21:23:09,740 - nornir.core.task -    ERROR -      start() - Host 'p2r4v': task 'fetch_vyos_config' failed with traceback:
Traceback (most recent call last):
  File "/home/aibix/streams/vyos5/.abx-vyos5/lib/python3.11/site-packages/nornir/core/task.py", line 99, in start
    r = self.task(self, **self.params)
        ^^^^^^^^^^^^^^^^^^^^^^^^^^^^^^
  File "/home/aibix/streams/vyos5/fetch_config.py", line 23, in fetch_vyos_config
    task=nautobot_create_device,
         ^^^^^^^^^^^^^^^^^^^^^^
NameError: name 'nautobot_create_device' is not defined

2024-07-11 21:23:27,687 - nornir.core.task -    ERROR -      start() - Host 'p2r7v': task 'fetch_vyos_config' failed with traceback:
Traceback (most recent call last):
  File "/home/aibix/streams/vyos5/.abx-vyos5/lib/python3.11/site-packages/nornir/core/task.py", line 99, in start
    r = self.task(self, **self.params)
        ^^^^^^^^^^^^^^^^^^^^^^^^^^^^^^
  File "/home/aibix/streams/vyos5/fetch_config.py", line 23, in fetch_vyos_config
    task=nautobot_create_device,
         ^^^^^^^^^^^^^^^^^^^^^^
NameError: name 'nautobot_create_device' is not defined

2024-07-11 21:29:55,583 -  nornir.core -     INFO -        run() - Running task 'fetch_vyos_config' with args {} on 1 hosts
2024-07-11 21:29:59,395 - nornir.core.task -    ERROR -      start() - Host 'p2r1v': task 'fetch_vyos_config' failed with traceback:
Traceback (most recent call last):
  File "/home/aibix/streams/vyos5/.abx-vyos5/lib/python3.11/site-packages/nornir/core/task.py", line 99, in start
    r = self.task(self, **self.params)
        ^^^^^^^^^^^^^^^^^^^^^^^^^^^^^^
  File "/home/aibix/streams/vyos5/fetch_config.py", line 23, in fetch_vyos_config
    task=nautobot_create_device,
         ^^^^^^^^^^^^^^^^^^^^^^
NameError: name 'nautobot_create_device' is not defined

2024-07-11 21:30:21,412 -  nornir.core -     INFO -        run() - Running task 'fetch_vyos_config' with args {} on 1 hosts
2024-07-11 21:30:25,325 - nornir.core.task -    ERROR -      start() - Host 'p2r1v': task 'fetch_vyos_config' failed with traceback:
Traceback (most recent call last):
  File "/home/aibix/streams/vyos5/.abx-vyos5/lib/python3.11/site-packages/nornir/core/task.py", line 99, in start
    r = self.task(self, **self.params)
        ^^^^^^^^^^^^^^^^^^^^^^^^^^^^^^
  File "/home/aibix/streams/vyos5/fetch_config.py", line 23, in fetch_vyos_config
    task=nautobot_create_device,
         ^^^^^^^^^^^^^^^^^^^^^^
NameError: name 'nautobot_create_device' is not defined

2024-07-11 21:31:59,294 -  nornir.core -     INFO -        run() - Running task 'fetch_vyos_config' with args {} on 1 hosts
2024-07-11 21:32:03,090 - nornir.core.task -    ERROR -      start() - Host 'p2r1v': task 'fetch_vyos_config' failed with traceback:
Traceback (most recent call last):
  File "/home/aibix/streams/vyos5/.abx-vyos5/lib/python3.11/site-packages/nornir/core/task.py", line 99, in start
    r = self.task(self, **self.params)
        ^^^^^^^^^^^^^^^^^^^^^^^^^^^^^^
  File "/home/aibix/streams/vyos5/fetch_config.py", line 23, in fetch_vyos_config
    task=nautobot_create_device,
         ^^^^^^^^^^^^^^^^^^^^^^
NameError: name 'nautobot_create_device' is not defined

2024-07-11 21:33:32,232 -  nornir.core -     INFO -        run() - Running task 'fetch_vyos_config' with args {} on 1 hosts
2024-07-11 21:33:36,297 - nornir.core.task -    ERROR -      start() - Host 'p2r1v': task 'fetch_vyos_config' failed with traceback:
Traceback (most recent call last):
  File "/home/aibix/streams/vyos5/.abx-vyos5/lib/python3.11/site-packages/nornir/core/task.py", line 99, in start
    r = self.task(self, **self.params)
        ^^^^^^^^^^^^^^^^^^^^^^^^^^^^^^
  File "/home/aibix/streams/vyos5/fetch_config.py", line 23, in fetch_vyos_config
    task=nautobot_create_device,
         ^^^^^^^^^^^^^^^^^^^^^^
NameError: name 'nautobot_create_device' is not defined

2024-07-11 21:35:40,393 -  nornir.core -     INFO -        run() - Running task 'fetch_vyos_config' with args {} on 1 hosts
2024-07-11 21:36:26,371 -  nornir.core -     INFO -        run() - Running task 'fetch_vyos_config' with args {} on 1 hosts
2024-07-11 21:37:38,895 -  nornir.core -     INFO -        run() - Running task 'fetch_vyos_config' with args {} on 1 hosts
2024-07-11 21:38:42,505 -  nornir.core -     INFO -        run() - Running task 'fetch_vyos_config' with args {} on 1 hosts
2024-07-11 21:40:02,628 -  nornir.core -     INFO -        run() - Running task 'fetch_vyos_config' with args {} on 1 hosts
2024-07-11 21:40:46,771 -  nornir.core -     INFO -        run() - Running task 'fetch_vyos_config' with args {} on 1 hosts
2024-07-11 21:41:24,487 -  nornir.core -     INFO -        run() - Running task 'fetch_vyos_config' with args {} on 1 hosts
2024-07-11 21:41:48,552 -  nornir.core -     INFO -        run() - Running task 'fetch_vyos_config' with args {} on 1 hosts
2024-07-11 21:42:44,149 -  nornir.core -     INFO -        run() - Running task 'fetch_vyos_config' with args {} on 1 hosts
2024-07-11 21:43:00,754 -  nornir.core -     INFO -        run() - Running task 'fetch_vyos_config' with args {} on 1 hosts
2024-07-11 21:43:22,945 -  nornir.core -     INFO -        run() - Running task 'fetch_vyos_config' with args {} on 1 hosts
2024-07-11 21:48:50,914 -  nornir.core -     INFO -        run() - Running task 'fetch_vyos_config' with args {} on 1 hosts
2024-07-11 21:50:00,503 -  nornir.core -     INFO -        run() - Running task 'fetch_vyos_config' with args {} on 1 hosts
2024-07-11 22:05:19,552 -  nornir.core -     INFO -        run() - Running task 'fetch_vyos_config' with args {} on 1 hosts
2024-07-11 22:05:29,565 - nornir.core.task -    ERROR -      start() - Host 'p2r1v': task 'netmiko_send_command' failed with traceback:
Traceback (most recent call last):
  File "/home/aibix/streams/vyos5/.abx-vyos5/lib/python3.11/site-packages/netmiko/base_connection.py", line 1139, in establish_connection
    self.remote_conn_pre.connect(**ssh_connect_params)
  File "/home/aibix/streams/vyos5/.abx-vyos5/lib/python3.11/site-packages/paramiko/client.py", line 386, in connect
    sock.connect(addr)
TimeoutError: timed out

During handling of the above exception, another exception occurred:

Traceback (most recent call last):
  File "/home/aibix/streams/vyos5/.abx-vyos5/lib/python3.11/site-packages/nornir/core/task.py", line 99, in start
    r = self.task(self, **self.params)
        ^^^^^^^^^^^^^^^^^^^^^^^^^^^^^^
  File "/home/aibix/streams/vyos5/.abx-vyos5/lib/python3.11/site-packages/nornir_netmiko/tasks/netmiko_send_command.py", line 26, in netmiko_send_command
    net_connect = task.host.get_connection(CONNECTION_NAME, task.nornir.config)
                  ^^^^^^^^^^^^^^^^^^^^^^^^^^^^^^^^^^^^^^^^^^^^^^^^^^^^^^^^^^^^^
  File "/home/aibix/streams/vyos5/.abx-vyos5/lib/python3.11/site-packages/nornir/core/inventory.py", line 494, in get_connection
    self.open_connection(
  File "/home/aibix/streams/vyos5/.abx-vyos5/lib/python3.11/site-packages/nornir/core/inventory.py", line 546, in open_connection
    conn_obj.open(
  File "/home/aibix/streams/vyos5/.abx-vyos5/lib/python3.11/site-packages/nornir_netmiko/connections/netmiko.py", line 59, in open
    connection = ConnectHandler(**parameters)
                 ^^^^^^^^^^^^^^^^^^^^^^^^^^^^
  File "/home/aibix/streams/vyos5/.abx-vyos5/lib/python3.11/site-packages/netmiko/ssh_dispatcher.py", line 401, in ConnectHandler
    return ConnectionClass(*args, **kwargs)
           ^^^^^^^^^^^^^^^^^^^^^^^^^^^^^^^^
  File "/home/aibix/streams/vyos5/.abx-vyos5/lib/python3.11/site-packages/netmiko/base_connection.py", line 490, in __init__
    self._open()
  File "/home/aibix/streams/vyos5/.abx-vyos5/lib/python3.11/site-packages/netmiko/base_connection.py", line 495, in _open
    self.establish_connection()
  File "/home/aibix/streams/vyos5/.abx-vyos5/lib/python3.11/site-packages/netmiko/base_connection.py", line 1161, in establish_connection
    raise NetmikoTimeoutException(msg)
netmiko.exceptions.NetmikoTimeoutException: TCP connection to device failed.

Common causes of this problem are:
1. Incorrect hostname or IP address.
2. Wrong TCP port.
3. Intermediate firewall blocking access.

Device settings: vyos 10.20.30.21:22



2024-07-11 22:05:29,565 - nornir.core.task -    ERROR -      start() - Host 'p2r1v': task 'fetch_vyos_config' failed with traceback:
Traceback (most recent call last):
  File "/home/aibix/streams/vyos5/.abx-vyos5/lib/python3.11/site-packages/nornir/core/task.py", line 99, in start
    r = self.task(self, **self.params)
        ^^^^^^^^^^^^^^^^^^^^^^^^^^^^^^
  File "/home/aibix/streams/vyos5/fetch_config.py", line 7, in fetch_vyos_config
    config_result = task.run(
                    ^^^^^^^^^
  File "/home/aibix/streams/vyos5/.abx-vyos5/lib/python3.11/site-packages/nornir/core/task.py", line 174, in run
    raise NornirSubTaskError(task=run_task, result=r)
nornir.core.exceptions.NornirSubTaskError: Subtask: netmiko_send_command (failed)


2024-07-11 22:06:58,647 -  nornir.core -     INFO -        run() - Running task 'fetch_vyos_config' with args {} on 1 hosts
2024-07-11 22:14:49,551 -  nornir.core -     INFO -        run() - Running task 'fetch_vyos_config' with args {} on 1 hosts
